Workbook
Name case: IS!$Q$24
Name circ: 'S&U and Opening BS'!$I$10
Name CostOfDebt: #REF!
Name Days: Inputs!$E$9
Name FYE: Inputs!$E$7
Name IQ_CAPEX_7YR_ANN_GROWTH: "c109"
Name IQ_CAPEX_BNK: "c110"
Name IQ_CAPEX_BR: "c111"
Name IQ_CAPEX_FIN: "c112"
Name IQ_CAPEX_INS: "c113"
Name IQ_CAPEX_UTI: "c114"
Name IQ_CAPITAL_LEASE: "c115"
Name IQ_CAPITAL_LEASES: "c115"
Name IQ_CASH: "c118"
Name IQ_CASH_ACQUIRE_CF: "c1630"
Name IQ_CASH_CONVERSION: "c117"
Name IQ_CASH_DUE_BANKS: "c118"
Name IQ_CASH_EQUIV: "c118"
Name IQ_CASH_FINAN: "c119"
Name IQ_CASH_INTEREST: "c120"
Name IQ_CASH_INVEST: "c121"
Name IQ_CASH_OPER: "c122"
Name IQ_CASH_SEGREG: "c123"
Name IQ_CASH_ST: "c124"
Name IQ_CASH_ST_INVEST: "c124"
Name IQ_CASH_TAXES: "c125"
Name IQ_CFO_10YR_ANN_GROWTH: "c126"
Name IQ_CFO_1YR_ANN_GROWTH: "c127"
Name IQ_CFO_2YR_ANN_GROWTH: "c128"
Name IQ_CFO_3YR_ANN_GROWTH: "c129"
Name IQ_CFO_5YR_ANN_GROWTH: "c130"
Name IQ_CFO_7YR_ANN_GROWTH: "c131"
Name IQ_CFO_CURRENT_LIAB: "c132"
Name IQ_CHANGE_AP: "c133"
Name IQ_CHANGE_AP_BNK: "c134"
Name IQ_CHANGE_AP_BR: "c135"
Name IQ_CHANGE_AP_FIN: "c136"
Name IQ_CHANGE_AP_INS: "c137"
Name IQ_CHANGE_AP_REIT: "c138"
Name IQ_CHANGE_AP_UTI: "c139"
Name IQ_CHANGE_AR: "c140"
Name IQ_CHANGE_AR_BNK: "c141"
Name IQ_CHANGE_AR_BR: "c142"
Name IQ_CHANGE_AR_FIN: "c143"
Name IQ_CHANGE_AR_INS: "c144"
Name IQ_CHANGE_AR_REIT: "c145"
Name IQ_CHANGE_AR_UTI: "c146"
Name IQ_CHANGE_DEF_TAX: "c147"
Name IQ_CHANGE_DEPOSIT_ACCT: "c148"
Name IQ_CHANGE_INC_TAX: "c149"
Name IQ_CHANGE_INS_RES_LIAB: "c150"
Name IQ_CHANGE_INVENTORY: "c151"
Name IQ_CHANGE_OTHER_WORK_CAP: "c152"
Name IQ_CHANGE_OTHER_WORK_CAP_BNK: "c153"
Name IQ_CHANGE_OTHER_WORK_CAP_BR: "c154"
Name IQ_CHANGE_OTHER_WORK_CAP_FIN: "c155"
Name IQ_CHANGE_OTHER_WORK_CAP_INS: "c156"
Name IQ_CHANGE_OTHER_WORK_CAP_REIT: "c157"
Name IQ_CHANGE_OTHER_WORK_CAP_UTI: "c158"
Name IQ_CHANGE_TRADING_ASSETS: "c159"

Sheet Inputs
A3: X | B3: Company Name | E3: Brady Coporation | I3: ç cell F3 is named "Name"
B5: Sub-header | E5: Dollars in Millions, except per share | I5: ç cell F5 is named "Subheader"
B7: Last Fiscal Year End | E7: 45869 | F7: ç cell is named "FYE"
A9: X | B9: Days Assumption | E9: 365 | F9: ç cell is named "days"
A13: X

Sheet S&U and Opening BS
D2: Recapitalization Accounting?
D3: N | E3: "Y" for recap accounting
E4: "N" for purchase accounting
K5: Notes:
D6: Rollover Equity Ownership Percentage: | K6: No RECAP Logic
D7: 0
D9: Minimum Cash Balance: | G9: Transaction Fee | I9: Circ
D10: 5 | E10: $ in Millions | G10: 0.01 | I10: 1 | J10: 1 = "On"
J11: 0 = "Off"
D12: Current Share Price: | G12: Share Price as of:
D13: 88.88 | G13: 46056
A17: x | B17: ="Leveraged "&IF(D3="Y","Recapitalization","Buyout")&" for " &Name -> Leveraged Buyout for Brady Coporation
B18: Transaction Summary | N18: Transaction Date: | O18: =FYE -> 45869
B19: =Subheader -> Dollars in Millions, except per share
B22: Sources: | H22: Amount | I22: Percent | J22: Int. Rate | K22: Ownership | L22: Term | M22: Points | N22: Fees | O22: Amort.
C23: Cash | H23: =H79-D10 -> 169.349 | I23: =H23/$H$29 -> 0.033066769 | J23: 0.038
C24: Bank Revolver | H24: =H29-H23-H25-H26-H28 -> 342.79357 | I24: =H24/$H$29 -> 0.066933231 | J24: 0.055 | L24: 7 | M24: 0.0225 | N24: =H24*M24 -> 7.7128554 | O24: =N24/L24 -> 1.1018365
C25: Bank Term Loan | H25: =I25*$H$29 -> 1536.4277 | I25: 0.3 | J25: 0.065 | L25: 7 | M25: 0.0225 | N25: =H25*M25 -> 34.569624 | O25: =N25/L25 -> 4.9385177
C26: Subordinated Debentures | H26: =I26*$H$29 -> 819.42812 | I26: 0.16 | J26: 0.085 | K26: 0 | L26: 10 | M26: 0.03 | N26: =H26*M26 -> 24.582843 | O26: =N26/L26 -> 2.4582843
C27: Rollover Equity (non-cash) | K27: 0
C28: Sponsor Equity | H28: =I28*$H$29 -> 2253.4273 | I28: 0.44 | K28: =1-SUM(K24:K27) -> 1
D29: Total Sources | H29: =H37 -> 5121.4257 | I29: =SUM(I23:I28) -> 1 | K29: =SUM(K24:K28) -> 1 | N29: =SUM(N24:N28) -> 66.865322 | O29: =SUM(O24:O28) -> 8.4986385
B31: Uses:
C32: ="Purchase of Equity @ "&TEXT(H41,"$0.00")&" per share" -> Purchase of Equity @ $102.21 per share | H32: =H44 -> 4905.737
C33: =C27 -> Rollover Equity (non-cash)
C34: Refinance Existing Debt | H34: =H99 -> 99.766
C35: Financing Fees | H35: =N29 -> 66.865322
C36: ="Transaction Expenses @ "&TEXT(G10,"0.0%") -> Transaction Expenses @ 1.0% | H36: =G10*H32 -> 49.05737
A37: x | D37: Total Uses | H37: =SUM(H32:H36) -> 5121.4257
B39: Purchase Price Calculation | J39: Summary Financial Ratios
B40: =IF(D3="y","Total Shares Purchased by Equity Sponsor","Total Potential Shares") -> Total Potential Shares | H40: =H49 -> 48.461697 | M40: =YEAR(FYE) -> 2025 | N40: =M40+1 -> 2026 | O40: =N40+1 -> 2027
B41: ="x Purchase Price Per Share @ "&TEXT(H41/D13-1,"0.0%")&" Premium" -> x Purchase Price Per Share @ 15.0% Premium | H41: 102.21 | J41: EBITDA | M41: =IS!H14 -> 277.277 | N41: =IS!I14 -> 306.73205 | O41: =IS!J14 -> 335.09921
H42: =H40*H41 -> 4953.2701 | J42: EBITDA/Cash Interest | M42: =Ratios!H26 -> 1.4719585 | N42: =Ratios!I26 -> 1.6489625 | O42: =Ratios!J26 -> 1.8720746
B43: Less: Option Proceeds | H43: =-H58 -> -47.533023 | J43: EBITDA-CapEx/Cash Interest | M43: =Ratios!H31 -> 1.3255627 | N43: =Ratios!I31 -> 1.4339262 | O43: =Ratios!J31 -> 1.6656011 | Q43: Limits
B44: = Equity Purchase Price (a) | H44: =SUM(H42:H43) -> 4905.737 | J44: Senior Debt/EBITDA | M44: =Ratios!H42 -> 6.777415 | N44: =Ratios!I42 -> 5.847085 | O44: =Ratios!J42 -> 4.8465704 | Q44: 7
J45: Total Debt/EBITDA | M45: =Ratios!H43 -> 9.7326839 | N45: =Ratios!I43 -> 8.5185636 | O45: =Ratios!J43 -> 7.2919004 | Q45: 10
B46: Share Information | J46: Equity as % of Total Capitalization | M46: =Ratios!H40 -> 0.44959438 | N46: =Ratios!I40 -> 0.4600207 | O46: =Ratios!J40 -> 0.4935887
B47: Shares Outstanding (mm) | H47: =43.555822+3.538628 -> 47.09445
B48: + Options Outstanding (In The Money) | H48: =G58 -> 1.367247 | N48: Year 6 | O48: Year 7 | Q48: Up to
B49: = Total Potential Shares | H49: =SUM(H47:H48) -> 48.461697 | J49: Cumulative Bank Debt Paydown | N49: =Ratios!N46 -> 0.65946219 | O49: =Ratios!O46 -> 0.83779912 | Q49: 0.6
...

Sheet IS
B1: ='S&U and Opening BS'!$B$17 -> Leveraged Buyout for Brady Coporation
B2: Income Statement | N2: Transaction Date: | O2: =FYE -> 45869
B3: =Subheader -> Dollars in Millions, except per share
H5: Pro Forma | I5: Projected Fiscal Year
H6: 2025 | I6: =H6+1 -> 2026 | J6: =I6+1 -> 2027 | K6: =J6+1 -> 2028 | L6: =K6+1 -> 2029 | M6: =L6+1 -> 2030 | N6: =M6+1 -> 2031 | O6: =N6+1 -> 2032
A8: x | B8: Revenues | H8: 1513.605 | I8: =H8*(1+I32) -> 1589.2853 | J8: =I8*(1+J32) -> 1667.1602 | K8: =J8*(1+K32) -> 1747.1839 | L8: =K8*(1+L32) -> 1829.3016 | M8: =L8*(1+M32) -> 1913.4494 | N8: =M8*(1+N32) -> 1999.5547 | O8: =N8*(1+O32) -> 2087.5351
B9: Cost of Sales (excluding Depreciation) | H9: =752.783-H16 -> 712.144 | I9: =(1-I36)*I8 -> 739.01764 | J9: =(1-J36)*J8 -> 768.56086 | K9: =(1-K36)*K8 -> 798.46305 | L9: =(1-L36)*L8 -> 828.67361 | M9: =(1-M36)*M8 -> 859.1388 | N9: =(1-N36)*N8 -> 889.80182 | O9: =(1-O36)*O8 -> 920.60296
C10: Gross Profit | H10: =H8-H9 -> 801.461 | I10: =I8-I9 -> 850.26761 | J10: =J8-J9 -> 898.59936 | K10: =K8-K9 -> 948.72087 | L10: =L8-L9 -> 1000.628 | M10: =M8-M9 -> 1054.3106 | N10: =N8-N9 -> 1109.7528 | O10: =O8-O9 -> 1166.9321
B12: Selling, general and administrative costs | H12: 444.295 | I12: =I8*I37 -> 460.89272 | J12: =J8*J37 -> 478.47499 | K12: =K8*K37 -> 496.20023 | L12: =L8*L37 -> 514.03374 | M12: =M8*M37 -> 531.93894 | N12: =N8*N37 -> 549.87753 | O12: =O8*O37 -> 567.80954
B13: Research and development | H13: 79.889 | I13: =I38*I8 -> 82.642833 | J13: =J38*J8 -> 85.025172 | K13: =K38*K8 -> 89.10638 | L13: =L38*L8 -> 93.29438 | M13: =M38*M8 -> 97.585921 | N13: =N38*N8 -> 101.97729 | O13: =O38*O8 -> 106.46429
A14: x | C14: EBITDA | H14: =H10-H12-H13 -> 277.277 | I14: =I10-I12-I13 -> 306.73205 | J14: =J10-J12-J13 -> 335.09921 | K14: =K10-K12-K13 -> 363.41425 | L14: =L10-L12-L13 -> 393.29984 | M14: =M10-M12-M13 -> 424.78577 | N14: =N10-N12-N13 -> 457.89802 | O14: =O10-O12-O13 -> 492.65828
B16: Depreciation and amortization | H16: 40.639 | I16: ='BS and Cash Flow'!I91 -> 42 | J16: ='BS and Cash Flow'!J91 -> 44.350223 | K16: ='BS and Cash Flow'!K91 -> 40.189172 | L16: ='BS and Cash Flow'!L91 -> 35.492577 | M16: ='BS and Cash Flow'!M91 -> 30.236818 | N16: ='BS and Cash Flow'!N91 -> 24.399078 | O16: ='BS and Cash Flow'!O91 -> 17.957511
A17: x | C17: EBIT | H17: =H14-H16 -> 236.638 | I17: =I14-I16 -> 264.73205 | J17: =J14-J16 -> 290.74898 | K17: =K14-K16 -> 323.22508 | L17: =L14-L16 -> 357.80726 | M17: =M14-M16 -> 394.54896 | N17: =N14-N16 -> 433.49894 | O17: =O14-O16 -> 474.70076
B19: Interest Expense | G19: Rate:
C20: Interest Income | G20: ='S&U and Opening BS'!J23 -> 0.038 | H20: =G20*-'S&U and Opening BS'!M79 -> -0.19 | I20: =-AVERAGE('BS and Cash Flow'!H8:I8)*IS!$G$20 -> -0.19 | J20: =-AVERAGE('BS and Cash Flow'!I8:J8)*IS!$G$20 -> -0.19 | K20: =-AVERAGE('BS and Cash Flow'!J8:K8)*IS!$G$20 -> -0.19 | L20: =-AVERAGE('BS and Cash Flow'!K8:L8)*IS!$G$20 -> -0.19 | M20: =-AVERAGE('BS and Cash Flow'!L8:M8)*IS!$G$20 -> -0.19 | N20: =-AVERAGE('BS and Cash Flow'!M8:N8)*IS!$G$20 -> -0.19 | O20: =-AVERAGE('BS and Cash Flow'!N8:O8)*IS!$G$20 -> -0.19
C21: Bank Revolver | G21: ='S&U and Opening BS'!J24 -> 0.055 | H21: =G21*'S&U and Opening BS'!M100 -> 18.853646 | I21: =AVERAGE('BS and Cash Flow'!H29:I29)*IS!$G$21 -> 16.495992 | J21: =AVERAGE('BS and Cash Flow'!I29:J29)*IS!$G$21 -> 9.4796585 | K21: =AVERAGE('BS and Cash Flow'!J29:K29)*IS!$G$21 -> 5.5570061 | L21: =AVERAGE('BS and Cash Flow'!K29:L29)*IS!$G$21 -> 8.4689393 | M21: =AVERAGE('BS and Cash Flow'!L29:M29)*IS!$G$21 -> 11.901675 | N21: =AVERAGE('BS and Cash Flow'!M29:N29)*IS!$G$21 -> 13.435569 | O21: =AVERAGE('BS and Cash Flow'!N29:O29)*IS!$G$21 -> 12.946786
C22: Bank Term Loan | G22: ='S&U and Opening BS'!J25 -> 0.065 | H22: =G22*'S&U and Opening BS'!M101 -> 99.867802 | I22: =AVERAGE('BS and Cash Flow'!H30:I30)*IS!$G$22 -> 99.867802 | J22: =AVERAGE('BS and Cash Flow'!I30:J30)*IS!$G$22 -> 99.867802 | K22: =AVERAGE('BS and Cash Flow'!J30:K30)*IS!$G$22 -> 92.589563 | L22: =AVERAGE('BS and Cash Flow'!K30:L30)*IS!$G$22 -> 75.324544 | M22: =AVERAGE('BS and Cash Flow'!L30:M30)*IS!$G$22 -> 55.350984 | N22: =AVERAGE('BS and Cash Flow'!M30:N30)*IS!$G$22 -> 35.377423 | O22: =AVERAGE('BS and Cash Flow'!N30:O30)*IS!$G$22 -> 15.403863
C23: Subordinated Debentures | G23: ='S&U and Opening BS'!J26 -> 0.085 | H23: =G23*'S&U and Opening BS'!M102 -> 69.65139 | I23: =AVERAGE('BS and Cash Flow'!H31:I31)*IS!$G$23 -> 69.65139 | J23: =AVERAGE('BS and Cash Flow'!I31:J31)*IS!$G$23 -> 69.65139 | K23: =AVERAGE('BS and Cash Flow'!J31:K31)*IS!$G$23 -> 69.65139 | L23: =AVERAGE('BS and Cash Flow'!K31:L31)*IS!$G$23 -> 69.65139 | M23: =AVERAGE('BS and Cash Flow'!L31:M31)*IS!$G$23 -> 69.65139 | N23: =AVERAGE('BS and Cash Flow'!M31:N31)*IS!$G$23 -> 69.65139 | O23: =AVERAGE('BS and Cash Flow'!N31:O31)*IS!$G$23 -> 69.65139 | Q23: Case
C24: Amortization of Deferred Financing Fees | H24: ='S&U and Opening BS'!$O$29 -> 8.4986385 | I24: ='S&U and Opening BS'!$O$29 -> 8.4986385 | J24: ='S&U and Opening BS'!$O$29 -> 8.4986385 | K24: ='S&U and Opening BS'!$O$29 -> 8.4986385 | L24: ='S&U and Opening BS'!$O$29 -> 8.4986385 | M24: ='S&U and Opening BS'!$O$29 -> 8.4986385 | N24: ='S&U and Opening BS'!$O$29 -> 8.4986385 | O24: ='S&U and Opening BS'!$O$29 -> 8.4986385 | Q24: 2 | R24: 1 = Upside Case
A25: x | D25: Net Interest Expense | H25: =SUM(H20:H24) -> 196.68148 | I25: =SUM(I20:I24) -> 194.32382 | J25: =SUM(J20:J24) -> 187.30749 | K25: =SUM(K20:K24) -> 176.1066 | L25: =SUM(L20:L24) -> 161.75351 | M25: =SUM(M20:M24) -> 145.21269 | N25: =SUM(N20:N24) -> 126.77302 | O25: =SUM(O20:O24) -> 106.31068 | R25: 2 = Base Case
R26: 3 = Downside Case
B27: Pretax Income | H27: =H17-H25 -> 39.956524 | I27: =I17-I25 -> 70.408232 | J27: =J17-J25 -> 103.44149 | K27: =K17-K25 -> 147.11849 | L27: =L17-L25 -> 196.05375 | M27: =M17-M25 -> 249.33627 | N27: =N17-N25 -> 306.72592 | O27: =O17-O25 -> 368.39009
C28: Taxes | H28: 47.841 | I28: =I44*I27 -> 14.785729 | J28: =J44*J27 -> 21.722714 | K28: =K44*K27 -> 30.894882 | L28: =L44*L27 -> 41.171287 | M28: =M44*M27 -> 52.360617 | N28: =N44*N27 -> 64.412443 | O28: =O44*O27 -> 77.361918
A29: x | B29: Net Income | H29: =H27-H28 -> -7.8844763 | I29: =I27-I28 -> 55.622503 | J29: =J27-J28 -> 81.71878 | K29: =K27-K28 -> 116.2236 | L29: =L27-L28 -> 154.88246 | M29: =M27-M28 -> 196.97565 | N29: =N27-N28 -> 242.31348 | O29: =O27-O28 -> 291.02817
Q31: Step
B32: Revenue Growth Rate | I32: =CHOOSE(case,I33,I34,I35) -> 0.05 | J32: =CHOOSE(case,J33,J34,J35) -> 0.049 | K32: =CHOOSE(case,K33,K34,K35) -> 0.048 | L32: =CHOOSE(case,L33,L34,L35) -> 0.047 | M32: =CHOOSE(case,M33,M34,M35) -> 0.046 | N32: =CHOOSE(case,N33,N34,N35) -> 0.045 | O32: =CHOOSE(case,O33,O34,O35) -> 0.044 | Q32: =CHOOSE(case,Q33,Q34,Q35) -> -0.001
H33: Upside | I33: 0.06 | J33: =I33+$Q$33 -> 0.06 | K33: =J33+$Q$33 -> 0.06 | L33: =K33+$Q$33 -> 0.06 | M33: =L33+$Q$33 -> 0.06 | N33: =M33+$Q$33 -> 0.06 | O33: =N33+$Q$33 -> 0.06 | Q33: 0
H34: Base | I34: 0.05 | J34: =I34+$Q$32 -> 0.049 | K34: =J34+$Q$32 -> 0.048 | L34: =K34+$Q$32 -> 0.047 | M34: =L34+$Q$32 -> 0.046 | N34: =M34+$Q$32 -> 0.045 | O34: =N34+$Q$32 -> 0.044 | Q34: -0.001
H35: Downside | I35: 0.04 | J35: =I35+$Q$32 -> 0.039 | K35: =J35+$Q$32 -> 0.038 | L35: =K35+$Q$32 -> 0.037 | M35: =L35+$Q$32 -> 0.036 | N35: =M35+$Q$32 -> 0.035 | O35: =N35+$Q$32 -> 0.034 | Q35: -0.003
B36: Gross Margin | H36: =H10/H8 -> 0.52950473 | I36: 0.535 | J36: =I36+$Q$36 -> 0.539 | K36: =J36+$Q$36 -> 0.543 | L36: =K36+$Q$36 -> 0.547 | M36: =L36+$Q$36 -> 0.551 | N36: =M36+$Q$36 -> 0.555 | O36: =N36+$Q$36 -> 0.559 | Q36: 0.004
B37: Selling Marketing & Delivery as % of Sales | H37: =H12/H8 -> 0.29353431 | I37: 0.29 | J37: =I37+$Q$37 -> 0.287 | K37: =J37+$Q$37 -> 0.284 | L37: =K37+$Q$37 -> 0.281 | M37: =L37+$Q$37 -> 0.278 | N37: =M37+$Q$37 -> 0.275 | O37: =N37+$Q$37 -> 0.272 | Q37: -0.003
B38: Research and development as % of Sales | H38: =H13/H8 -> 0.052780613 | I38: 0.052 | J38: 0.051 | K38: =J38+$Q$38 -> 0.051 | L38: =K38+$Q$38 -> 0.051 | M38: =L38+$Q$38 -> 0.051 | N38: =M38+$Q$38 -> 0.051 | O38: =N38+$Q$38 -> 0.051 | Q38: 0
B40: Net Income Growth | I40: =I29/H29-1 -> -8.0546858 | J40: =J29/I29-1 -> 0.46916762 | K40: =K29/J29-1 -> 0.4222386 | L40: =L29/K29-1 -> 0.33262483 | M40: =M29/L29-1 -> 0.27177508 | N40: =N29/M29-1 -> 0.23016968 | O40: =O29/N29-1 -> 0.20103997
B41: EBITDA Margin | H41: =H14/H8 -> 0.1831898 | I41: =I14/I8 -> 0.193 | J41: =J14/J8 -> 0.201 | K41: =K14/K8 -> 0.208 | L41: =L14/L8 -> 0.215 | M41: =M14/M8 -> 0.222 | N41: =N14/N8 -> 0.229 | O41: =O14/O8 -> 0.236
B42: EBIT Margin | H42: =H17/H8 -> 0.15634066 | I42: =I17/I8 -> 0.16657303 | J42: =J17/J8 -> 0.17439774 | K42: =K17/K8 -> 0.18499774 | L42: =L17/L8 -> 0.19559774 | M42: =M17/M8 -> 0.20619774 | N42: =N17/N8 -> 0.21679774 | O42: =O17/O8 -> 0.22739774
A44: x | B44: Effective Tax Rate | H44: 0.21 | I44: =H44 -> 0.21 | J44: =I44 -> 0.21 | K44: =J44 -> 0.21 | L44: =K44 -> 0.21 | M44: =L44 -> 0.21 | N44: =M44 -> 0.21 | O44: =N44 -> 0.21
A47: x

Sheet BS and Cash Flow
B1: ='S&U and Opening BS'!$B$17 -> Leveraged Buyout for Brady Coporation
B2: Balance Sheet | N2: Transaction Date: | O2: =FYE -> 45869
B3: =Subheader -> Dollars in Millions, except per share
H5: =IS!H5 -> Pro Forma | I5: =IS!I5 -> Projected Fiscal Year
H6: 2025 | I6: =H6+1 -> 2026 | J6: =I6+1 -> 2027 | K6: =J6+1 -> 2028 | L6: =K6+1 -> 2029 | M6: =L6+1 -> 2030 | N6: =M6+1 -> 2031 | O6: =N6+1 -> 2032
A8: x | C8: ='S&U and Opening BS'!C79 -> Cash | H8: ='S&U and Opening BS'!M79 -> 5 | I8: =I73 -> 5 | J8: =J73 -> 5 | K8: =K73 -> 5 | L8: =L73 -> 5 | M8: =M73 -> 5 | N8: =N73 -> 5 | O8: =O73 -> 5
C9: ='S&U and Opening BS'!C80 -> Accounts Receivable, net | H9: ='S&U and Opening BS'!M80 -> 231.944 | I9: =(I81/Days)*IS!I8 -> 243.5412 | J9: =(J81/Days)*IS!J8 -> 248.62338 | K9: =(K81/Days)*IS!K8 -> 253.37709 | L9: =(L81/Days)*IS!L8 -> 257.76814 | M9: =(M81/Days)*IS!M8 -> 261.76198 | N9: =(N81/Days)*IS!N8 -> 265.32392 | O9: =(O81/Days)*IS!O8 -> 268.41926
C10: ='S&U and Opening BS'!C81 -> Inventories | H10: ='S&U and Opening BS'!M81 -> 200.881 | I10: =(I82/Days)*IS!I9 -> 208.46149 | J10: =(J82/Days)*IS!J9 -> 212.58373 | K10: =(K82/Days)*IS!K9 -> 216.47953 | L10: =(L82/Days)*IS!L9 -> 220.12955 | M10: =(M82/Days)*IS!M9 -> 223.51473 | N10: =(N82/Days)*IS!N9 -> 226.61644 | O10: =(O82/Days)*IS!O9 -> 229.41654
C11: ='S&U and Opening BS'!C82 -> Other Current Assets | H11: ='S&U and Opening BS'!M82 -> 14.661 | I11: =I83*IS!I8 -> 15.39405 | J11: =J83*IS!J8 -> 16.148358 | K11: =K83*IS!K8 -> 16.92348 | L11: =L83*IS!L8 -> 17.718883 | M11: =M83*IS!M8 -> 18.533952 | N11: =N83*IS!N8 -> 19.36798 | O11: =O83*IS!O8 -> 20.220171
B12: Total Current Assets: | H12: ='S&U and Opening BS'!M83 -> 452.486 | I12: =SUM(I8:I11) -> 472.39674 | J12: =SUM(J8:J11) -> 482.35546 | K12: =SUM(K8:K11) -> 491.7801 | L12: =SUM(L8:L11) -> 500.61656 | M12: =SUM(M8:M11) -> 508.81066 | N12: =SUM(N8:N11) -> 516.30834 | O12: =SUM(O8:O11) -> 523.05597
A14: x | C14: ='S&U and Opening BS'!C85 -> PP&E, net | H14: ='S&U and Opening BS'!M85 -> 225.572 | I14: =H14+I88-I91 -> 223.572 | J14: =I14+J88-J91 -> 216.1803 | K14: =J14+K88-K91 -> 209.4821 | L14: =K14+L88-L91 -> 203.56667 | M14: =L14+M88-M91 -> 198.5272 | N14: =M14+N88-N91 -> 194.46069 | O14: =N14+O88-O91 -> 191.46777
C15: ='S&U and Opening BS'!C86 -> Definite Life Intangibles | H15: ='S&U and Opening BS'!M86 -> 97.722 | I15: =H15+I94 -> 97.722 | J15: =I15+J94 -> 97.722 | K15: =J15+K94 -> 97.722 | L15: =K15+L94 -> 97.722 | M15: =L15+M94 -> 97.722 | N15: =M15+N94 -> 97.722 | O15: =N15+O94 -> 97.722
C16: ='S&U and Opening BS'!C87 -> Indefinite Life Intangibles | H16: ='S&U and Opening BS'!M87 -> 7.652 | I16: =H16 -> 7.652 | J16: =I16 -> 7.652 | K16: =J16 -> 7.652 | L16: =K16 -> 7.652 | M16: =L16 -> 7.652 | N16: =M16 -> 7.652 | O16: =N16 -> 7.652
C17: ='S&U and Opening BS'!C88 -> Goodwill | H17: ='S&U and Opening BS'!M88 -> 4390.471 | I17: =H17 -> 4390.471 | J17: =I17 -> 4390.471 | K17: =J17 -> 4390.471 | L17: =K17 -> 4390.471 | M17: =L17 -> 4390.471 | N17: =M17 -> 4390.471 | O17: =N17 -> 4390.471
C18: ='S&U and Opening BS'!C89 -> Long-Term Investment | H18: ='S&U and Opening BS'!M89 -> 0 | I18: 0 | J18: 0 | K18: 0 | L18: 0 | M18: 0 | N18: 0 | O18: 0
C19: ='S&U and Opening BS'!C90 -> Other Non-Current Assets | H19: ='S&U and Opening BS'!M90 -> 104.527 | I19: =H19 -> 104.527 | J19: =I19 -> 104.527 | K19: =J19 -> 104.527 | L19: =K19 -> 104.527 | M19: =L19 -> 104.527 | N19: =M19 -> 104.527 | O19: =N19 -> 104.527
C20: ='S&U and Opening BS'!C91 -> Deferred Financing Fees | H20: ='S&U and Opening BS'!M91 -> 66.865322 | I20: 0 | J20: 0 | K20: 0 | L20: 0 | M20: 0 | N20: 0 | O20: 0
B21: Total Assets: | H21: ='S&U and Opening BS'!M92 -> 5345.2953 | I21: =SUM(I12:I20) -> 5296.3408 | J21: =SUM(J12:J20) -> 5298.9078 | K21: =SUM(K12:K20) -> 5301.6342 | L21: =SUM(L12:L20) -> 5304.5553 | M21: =SUM(M12:M20) -> 5307.7099 | N21: =SUM(N12:N20) -> 5311.1411 | O21: =SUM(O12:O20) -> 5314.8958
A23: x | C23: ='S&U and Opening BS'!C94 -> Accounts Payable | H23: ='S&U and Opening BS'!M94 -> 105.028 | I23: =(I84/Days)*IS!I9 -> 108.99136 | J23: =(J84/Days)*IS!J9 -> 115.87521 | K23: =(K84/Days)*IS!K9 -> 123.00862 | L23: =(L84/Days)*IS!L9 -> 130.38717 | M23: =(M84/Days)*IS!M9 -> 138.00526 | N23: =(N84/Days)*IS!N9 -> 145.85611 | O23: =(O84/Days)*IS!O9 -> 153.93166
C24: ='S&U and Opening BS'!C95 -> Accrued Liabilities | H24: ='S&U and Opening BS'!M95 -> 98.204 | I24: =I85*IS!I9 -> 103.46247 | J24: =J85*IS!J9 -> 107.59852 | K24: =K85*IS!K9 -> 111.78483 | L24: =L85*IS!L9 -> 116.01431 | M24: =M85*IS!M9 -> 120.27943 | N24: =N85*IS!N9 -> 124.57226 | O24: =O85*IS!O9 -> 128.88441
C25: ='S&U and Opening BS'!C96 -> Other Current Liabilities | H25: ='S&U and Opening BS'!M96 -> 127.1 | I25: =I86*IS!I9 -> 133.02318 | J25: =J86*IS!J9 -> 138.34096 | K25: =K86*IS!K9 -> 143.72335 | L25: =L86*IS!L9 -> 149.16125 | M25: =M86*IS!M9 -> 154.64498 | N25: =N86*IS!N9 -> 160.16433 | O25: =O86*IS!O9 -> 165.70853
B26: Total Current Liabilities: | H26: ='S&U and Opening BS'!M97 -> 330.332 | I26: =SUM(I23:I25) -> 345.47701 | J26: =SUM(J23:J25) -> 361.81469 | K26: =SUM(K23:K25) -> 378.5168 | L26: =SUM(L23:L25) -> 395.56272 | M26: =SUM(M23:M25) -> 412.92968 | N26: =SUM(N23:N25) -> 430.59269 | O26: =SUM(O23:O25) -> 448.52461
A28: x | C28: ='S&U and Opening BS'!C99 -> Existing Long-Term Debt | H28: ='S&U and Opening BS'!M99 -> 0 | I28: 0 | J28: 0 | K28: 0 | L28: 0 | M28: 0 | N28: 0 | O28: 0
C29: ='S&U and Opening BS'!C100 -> Revolving Credit Facility | H29: ='S&U and Opening BS'!M100 -> 342.79357 | I29: =H29+I69 -> 257.06067 | J29: =I29+J69 -> 87.654184 | K29: =J29+K69 -> 114.41876 | L29: =K29+L69 -> 193.54266 | M29: =L29+M69 -> 239.24553 | N29: =M29+N69 -> 249.32063 | O29: =N29+O69 -> 221.4716
C30: ='S&U and Opening BS'!C101 -> Bank Term Loan | H30: ='S&U and Opening BS'!M101 -> 1536.4277 | I30: =H30+I66 -> 1536.4277 | J30: =I30+J66 -> 1536.4277 | K30: =J30+K66 -> 1312.4819 | L30: =K30+L66 -> 1005.1964 | M30: =L30+M66 -> 697.91082 | N30: =M30+N66 -> 390.62528 | O30: =N30+O66 -> 83.339735
C31: ='S&U and Opening BS'!C102 -> Subordinated Debt | H31: ='S&U and Opening BS'!M102 -> 819.42812 | I31: =H31 -> 819.42812 | J31: =I31 -> 819.42812 | K31: =J31 -> 819.42812 | L31: =K31 -> 819.42812 | M31: =L31 -> 819.42812 | N31: =M31 -> 819.42812 | O31: =N31 -> 819.42812
C32: ='S&U and Opening BS'!C103 -> Deferred Income Taxes | H32: ='S&U and Opening BS'!M103 -> 0 | I32: 0 | J32: 0 | K32: 0 | L32: 0 | M32: 0 | N32: 0 | O32: 0
C33: ='S&U and Opening BS'!C104 -> Other Long-Term Liabilities | H33: ='S&U and Opening BS'!M104 -> 111.944 | I33: =H33 -> 111.944 | J33: =I33 -> 111.944 | K33: =J33 -> 111.944 | L33: =K33 -> 111.944 | M33: =L33 -> 111.944 | N33: =M33 -> 111.944 | O33: =N33 -> 111.944
B34: Total Liabilities: | H34: ='S&U and Opening BS'!M105 -> 3140.9254 | I34: =SUM(I26:I33) -> 3070.3375 | J34: =SUM(J26:J33) -> 2917.2687 | K34: =SUM(K26:K33) -> 2736.7896 | L34: =SUM(L26:L33) -> 2525.6739 | M34: =SUM(M26:M33) -> 2281.4581 | N34: =SUM(N26:N33) -> 2001.9107 | O34: =SUM(O26:O33) -> 1684.7081
A36: x | B36: Total Equity: | H36: ='S&U and Opening BS'!M107 -> 2204.3699 | I36: =I21-I34 -> 2226.0033 | J36: =J21-J34 -> 2381.6391 | K36: =K21-K34 -> 2564.8446 | L36: =L21-L34 -> 2778.8814 | M36: =M21-M34 -> 3026.2517 | N36: =N21-N34 -> 3309.2303 | O36: =O21-O34 -> 3630.1877
B38: Total Liabilities and Equity: | H38: ='S&U and Opening BS'!M109 -> 5345.2953 | I38: =I34+I36 -> 5296.3408 | J38: =J34+J36 -> 5298.9078 | K38: =K34+K36 -> 5301.6342 | L38: =L34+L36 -> 5304.5553 | M38: =M34+M36 -> 5307.7099 | N38: =N34+N36 -> 5311.1411 | O38: =O34+O36 -> 5314.8958
C39: Check | H39: ='S&U and Opening BS'!M110 -> 0 | I39: 0 | J39: 0 | K39: 0 | L39: 0 | M39: 0 | N39: 0 | O39: 0
B41: ='S&U and Opening BS'!B17 -> Leveraged Buyout for Brady Coporation
B42: Cash Flow Statement | N42: Transaction Date: | O42: ='S&U and Opening BS'!$O$18 -> 45869
B43: =Subheader -> Dollars in Millions, except per share
I44: =IS!I5 -> Projected Fiscal Year
I45: =IS!I6 -> 2026 | J45: =IS!J6 -> 2027 | K45: =IS!K6 -> 2028 | L45: =IS!L6 -> 2029 | M45: =IS!M6 -> 2030 | N45: =IS!N6 -> 2031 | O45: =IS!O6 -> 2032
B47: Net Income | J47: =IS!J29 -> 81.71878 | K47: =IS!K29 -> 116.2236 | L47: =IS!L29 -> 154.88246 | M47: =IS!M29 -> 196.97565 | N47: =IS!N29 -> 242.31348 | O47: =IS!O29 -> 291.02817
B48: Depreciation and amortization | I48: =I91 -> 42 | J48: =J91 -> 44.350223 | K48: =K91 -> 40.189172 | L48: =L91 -> 35.492577 | M48: =M91 -> 30.236818 | N48: =N91 -> 24.399078 | O48: =O91 -> 17.957511
B49: Amortization of Financing Fees | I49: =IS!I24 -> 8.4986385 | J49: 0 | K49: 0 | L49: 0 | M49: 0 | N49: 0 | O49: 0
...

Sheet Ratios
B1: ='S&U and Opening BS'!$B$17 -> Leveraged Buyout for Brady Coporation
B2: Financial Ratios | N2: Transaction Date: | O2: =FYE -> 45869
B3: =Subheader -> Dollars in Millions, except per share
H5: =IS!H5 -> Pro Forma | I5: =IS!I5 -> Projected Fiscal Year
H6: =YEAR(FYE) -> 2025 | I6: =H6+1 -> 2026 | J6: =I6+1 -> 2027 | K6: =J6+1 -> 2028 | L6: =K6+1 -> 2029 | M6: =L6+1 -> 2030 | N6: =M6+1 -> 2031 | O6: =N6+1 -> 2032
A8: x | B8: Capitalization:
C9: Senior Debt | H9: ='BS and Cash Flow'!H29+'BS and Cash Flow'!H30 -> 1879.2213 | I9: ='BS and Cash Flow'!I29+'BS and Cash Flow'!I30 -> 1793.4884 | J9: ='BS and Cash Flow'!J29+'BS and Cash Flow'!J30 -> 1624.0819 | K9: ='BS and Cash Flow'!K29+'BS and Cash Flow'!K30 -> 1426.9007 | L9: ='BS and Cash Flow'!L29+'BS and Cash Flow'!L30 -> 1198.739 | M9: ='BS and Cash Flow'!M29+'BS and Cash Flow'!M30 -> 937.15636 | N9: ='BS and Cash Flow'!N29+'BS and Cash Flow'!N30 -> 639.9459 | O9: ='BS and Cash Flow'!O29+'BS and Cash Flow'!O30 -> 304.81134 | CS9: =SUM('BS and Cash Flow'!CS28:CS30) -> 0 | CT9: =SUM('BS and Cash Flow'!CT28:CT30) -> 0 | CU9: =SUM('BS and Cash Flow'!CU28:CU30) -> 0 | CV9: =SUM('BS and Cash Flow'!CV28:CV30) -> 0 | CW9: =SUM('BS and Cash Flow'!CW28:CW30) -> 0 | CX9: =SUM('BS and Cash Flow'!CX28:CX30) -> 0 | CY9: =SUM('BS and Cash Flow'!CY28:CY30) -> 0 | CZ9: =SUM('BS and Cash Flow'!CZ28:CZ30) -> 0
C10: Subordinated Debt | H10: ='BS and Cash Flow'!H31 -> 819.42812 | I10: ='BS and Cash Flow'!I31 -> 819.42812 | J10: ='BS and Cash Flow'!J31 -> 819.42812 | K10: ='BS and Cash Flow'!K31 -> 819.42812 | L10: ='BS and Cash Flow'!L31 -> 819.42812 | M10: ='BS and Cash Flow'!M31 -> 819.42812 | N10: ='BS and Cash Flow'!N31 -> 819.42812 | O10: ='BS and Cash Flow'!O31 -> 819.42812 | CS10: ='BS and Cash Flow'!CS31 -> 0 | CT10: ='BS and Cash Flow'!CT31 -> 0 | CU10: ='BS and Cash Flow'!CU31 -> 0 | CV10: ='BS and Cash Flow'!CV31 -> 0 | CW10: ='BS and Cash Flow'!CW31 -> 0 | CX10: ='BS and Cash Flow'!CX31 -> 0 | CY10: ='BS and Cash Flow'!CY31 -> 0 | CZ10: ='BS and Cash Flow'!CZ31 -> 0
C11: Total Debt | H11: =SUM(H9:H10) -> 2698.6494 | I11: =SUM(I9:I10) -> 2612.9165 | J11: =SUM(J9:J10) -> 2443.51 | K11: =SUM(K9:K10) -> 2246.3288 | L11: =SUM(L9:L10) -> 2018.1671 | M11: =SUM(M9:M10) -> 1756.5845 | N11: =SUM(N9:N10) -> 1459.374 | O11: =SUM(O9:O10) -> 1124.2395 | CS11: =SUM(CS9:CS10) -> 0 | CT11: =SUM(CT9:CT10) -> 0 | CU11: =SUM(CU9:CU10) -> 0 | CV11: =SUM(CV9:CV10) -> 0 | CW11: =SUM(CW9:CW10) -> 0 | CX11: =SUM(CX9:CX10) -> 0 | CY11: =SUM(CY9:CY10) -> 0 | CZ11: =SUM(CZ9:CZ10) -> 0
D12: Less: Cash | H12: ='BS and Cash Flow'!H8 -> 5 | I12: ='BS and Cash Flow'!I8 -> 5 | J12: ='BS and Cash Flow'!J8 -> 5 | K12: ='BS and Cash Flow'!K8 -> 5 | L12: ='BS and Cash Flow'!L8 -> 5 | M12: ='BS and Cash Flow'!M8 -> 5 | N12: ='BS and Cash Flow'!N8 -> 5 | O12: ='BS and Cash Flow'!O8 -> 5 | CS12: =-'BS and Cash Flow'!CS8 -> 0 | CT12: =-'BS and Cash Flow'!CT8 -> 0 | CU12: =-'BS and Cash Flow'!CU8 -> 0 | CV12: =-'BS and Cash Flow'!CV8 -> 0 | CW12: =-'BS and Cash Flow'!CW8 -> 0 | CX12: =-'BS and Cash Flow'!CX8 -> 0 | CY12: =-'BS and Cash Flow'!CY8 -> 0 | CZ12: =-'BS and Cash Flow'!CZ8 -> 0
C13: Net Debt | H13: =H11-H12 -> 2693.6494 | I13: =SUM(I11:I12) -> 2617.9165 | J13: =SUM(J11:J12) -> 2448.51 | K13: =SUM(K11:K12) -> 2251.3288 | L13: =SUM(L11:L12) -> 2023.1671 | M13: =SUM(M11:M12) -> 1761.5845 | N13: =SUM(N11:N12) -> 1464.374 | O13: =SUM(O11:O12) -> 1129.2395 | CS13: =SUM(CS11:CS12) -> 0 | CT13: =SUM(CT11:CT12) -> 0 | CU13: =SUM(CU11:CU12) -> 0 | CV13: =SUM(CV11:CV12) -> 0 | CW13: =SUM(CW11:CW12) -> 0 | CX13: =SUM(CX11:CX12) -> 0 | CY13: =SUM(CY11:CY12) -> 0 | CZ13: =SUM(CZ11:CZ12) -> 0
D15: Book Equity | H15: ='BS and Cash Flow'!H36 -> 2204.3699 | I15: ='BS and Cash Flow'!I36 -> 2226.0033 | J15: ='BS and Cash Flow'!J36 -> 2381.6391 | K15: ='BS and Cash Flow'!K36 -> 2564.8446 | L15: ='BS and Cash Flow'!L36 -> 2778.8814 | M15: ='BS and Cash Flow'!M36 -> 3026.2517 | N15: ='BS and Cash Flow'!N36 -> 3309.2303 | O15: ='BS and Cash Flow'!O36 -> 3630.1877 | CS15: ='BS and Cash Flow'!CS36 -> 0 | CT15: ='BS and Cash Flow'!CT36 -> 0 | CU15: ='BS and Cash Flow'!CU36 -> 0 | CV15: ='BS and Cash Flow'!CV36 -> 0 | CW15: ='BS and Cash Flow'!CW36 -> 0 | CX15: ='BS and Cash Flow'!CX36 -> 0 | CY15: ='BS and Cash Flow'!CY36 -> 0 | CZ15: ='BS and Cash Flow'!CZ36 -> 0
C16: Total Capitalization | H16: =H11+H15 -> 4903.0193 | I16: =I11+I15 -> 4838.9198 | J16: =J11+J15 -> 4825.1491 | K16: =K11+K15 -> 4811.1734 | L16: =L11+L15 -> 4797.0485 | M16: =M11+M15 -> 4782.8362 | N16: =N11+N15 -> 4768.6044 | O16: =O11+O15 -> 4754.4272 | CS16: =CS11+CS15 -> 0 | CT16: =CT11+CT15 -> 0 | CU16: =CU11+CU15 -> 0 | CV16: =CV11+CV15 -> 0 | CW16: =CW11+CW15 -> 0 | CX16: =CX11+CX15 -> 0 | CY16: =CY11+CY15 -> 0 | CZ16: =CZ11+CZ15 -> 0
A18: x | B18: Coverage Ratios:
C19: Total Interest Expense | H19: =SUM(IS!H21:H24) -> 196.87148 | I19: =SUM(IS!I21:I24) -> 194.51382 | J19: =SUM(IS!J21:J24) -> 187.49749 | K19: =SUM(IS!K21:K24) -> 176.2966 | L19: =SUM(IS!L21:L24) -> 161.94351 | M19: =SUM(IS!M21:M24) -> 145.40269 | N19: =SUM(IS!N21:N24) -> 126.96302 | O19: =SUM(IS!O21:O24) -> 106.50068 | CS19: =SUM(IS!CS21:CS24) -> 0 | CT19: =SUM(IS!CT21:CT24) -> 0 | CU19: =SUM(IS!CU21:CU24) -> 0 | CV19: =SUM(IS!CV21:CV24) -> 0 | CW19: =SUM(IS!CW21:CW24) -> 0 | CX19: =SUM(IS!CX21:CX24) -> 0 | CY19: =SUM(IS!CY21:CY24) -> 0 | CZ19: =SUM(IS!CZ21:CZ24) -> 0
C20: Net Interest Expense | H20: =IS!H25 -> 196.68148 | I20: =IS!I25 -> 194.32382 | J20: =IS!J25 -> 187.30749 | K20: =IS!K25 -> 176.1066 | L20: =IS!L25 -> 161.75351 | M20: =IS!M25 -> 145.21269 | N20: =IS!N25 -> 126.77302 | O20: =IS!O25 -> 106.31068 | CS20: =IS!CS25 -> 0 | CT20: =IS!CT25 -> 0 | CU20: =IS!CU25 -> 0 | CV20: =IS!CV25 -> 0 | CW20: =IS!CW25 -> 0 | CX20: =IS!CX25 -> 0 | CY20: =IS!CY25 -> 0 | CZ20: =IS!CZ25 -> 0
C21: Cash Interest Expense (a) | H21: =Ratios!H19-IS!H24 -> 188.37284 | I21: =Ratios!I19-IS!I24 -> 186.01518 | J21: =Ratios!J19-IS!J24 -> 178.99885 | K21: =Ratios!K19-IS!K24 -> 167.79796 | L21: =Ratios!L19-IS!L24 -> 153.44487 | M21: =Ratios!M19-IS!M24 -> 136.90405 | N21: =Ratios!N19-IS!N24 -> 118.46438 | O21: =Ratios!O19-IS!O24 -> 98.002039 | CS21: =SUM(IS!CS21:CS23) -> 0 | CT21: =SUM(IS!CT21:CT23) -> 0 | CU21: =SUM(IS!CU21:CU23) -> 0 | CV21: =SUM(IS!CV21:CV23) -> 0 | CW21: =SUM(IS!CW21:CW23) -> 0 | CX21: =SUM(IS!CX21:CX23) -> 0 | CY21: =SUM(IS!CY21:CY23) -> 0 | CZ21: =SUM(IS!CZ21:CZ23) -> 0
C23: EBITDA | H23: =IS!H14 -> 277.277 | I23: =IS!I14 -> 306.73205 | J23: =IS!J14 -> 335.09921 | K23: =IS!K14 -> 363.41425 | L23: =IS!L14 -> 393.29984 | M23: =IS!M14 -> 424.78577 | N23: =IS!N14 -> 457.89802 | O23: =IS!O14 -> 492.65828 | CS23: =IS!CS14 -> 0 | CT23: =IS!CT14 -> 0 | CU23: =IS!CU14 -> 0 | CV23: =IS!CV14 -> 0 | CW23: =IS!CW14 -> 0 | CX23: =IS!CX14 -> 0 | CY23: =IS!CY14 -> 0 | CZ23: =IS!CZ14 -> 0
D24: vs. Total Interest | H24: =H23/H19 -> 1.4084163 | I24: =I23/I19 -> 1.5769165 | J24: =J23/J19 -> 1.7872197 | K24: =K23/K19 -> 2.0613799 | L24: =L23/L19 -> 2.4286236 | M24: =M23/M19 -> 2.9214438 | N24: =N23/N19 -> 3.6065463 | O24: =O23/O19 -> 4.6258699 | CS24: =CS$23/CS19 -> #DIV/0! | CT24: =CT$23/CT19 -> #DIV/0! | CU24: =CU$23/CU19 -> #DIV/0! | CV24: =CV$23/CV19 -> #DIV/0! | CW24: =CW$23/CW19 -> #DIV/0! | CX24: =CX$23/CX19 -> #DIV/0! | CY24: =CY$23/CY19 -> #DIV/0! | CZ24: =CZ$23/CZ19 -> #DIV/0!
D25: vs. Net Interest | H25: =H23/H20 -> 1.4097769 | I25: =I23/I20 -> 1.5784583 | J25: =J23/J20 -> 1.7890326 | K25: =K23/K20 -> 2.0636039 | L25: =L23/L20 -> 2.4314763 | M25: =M23/M20 -> 2.9252663 | N25: =N23/N20 -> 3.6119516 | O25: =O23/O20 -> 4.6341373 | CS25: =CS$23/CS20 -> #DIV/0! | CT25: =CT$23/CT20 -> #DIV/0! | CU25: =CU$23/CU20 -> #DIV/0! | CV25: =CV$23/CV20 -> #DIV/0! | CW25: =CW$23/CW20 -> #DIV/0! | CX25: =CX$23/CX20 -> #DIV/0! | CY25: =CY$23/CY20 -> #DIV/0! | CZ25: =CZ$23/CZ20 -> #DIV/0!
D26: vs. Cash Interest (a) | H26: =H23/H21 -> 1.4719585 | I26: =I23/I21 -> 1.6489625 | J26: =J23/J21 -> 1.8720746 | K26: =K23/K21 -> 2.1657847 | L26: =L23/L21 -> 2.5631344 | M26: =M23/M21 -> 3.1027992 | N26: =N23/N21 -> 3.8652801 | O26: =O23/O21 -> 5.0270207 | CS26: =CS$23/CS21 -> #DIV/0! | CT26: =CT$23/CT21 -> #DIV/0! | CU26: =CU$23/CU21 -> #DIV/0! | CV26: =CV$23/CV21 -> #DIV/0! | CW26: =CW$23/CW21 -> #DIV/0! | CX26: =CX$23/CX21 -> #DIV/0! | CY26: =CY$23/CY21 -> #DIV/0! | CZ26: =CZ$23/CZ21 -> #DIV/0!
C28: EBITDA - CAPX | H28: =Ratios!H23-'BS and Cash Flow'!H88 -> 249.7 | I28: =Ratios!I23-'BS and Cash Flow'!I88 -> 266.73205 | J28: =Ratios!J23-'BS and Cash Flow'!J88 -> 298.14069 | K28: =Ratios!K23-'BS and Cash Flow'!K88 -> 329.92328 | L28: =Ratios!L23-'BS and Cash Flow'!L88 -> 363.72269 | M28: =Ratios!M23-'BS and Cash Flow'!M88 -> 399.58843 | N28: =Ratios!N23-'BS and Cash Flow'!N88 -> 437.56545 | O28: =Ratios!O23-'BS and Cash Flow'!O88 -> 477.69368 | CS28: =IS!CS14-'BS and Cash Flow'!CS88 -> 0 | CT28: =IS!CT14-'BS and Cash Flow'!CT88 -> 0 | CU28: =IS!CU14-'BS and Cash Flow'!CU88 -> 0 | CV28: =IS!CV14-'BS and Cash Flow'!CV88 -> 0 | CW28: =IS!CW14-'BS and Cash Flow'!CW88 -> 0 | CX28: =IS!CX14-'BS and Cash Flow'!CX88 -> 0 | CY28: =IS!CY14-'BS and Cash Flow'!CY88 -> 0 | CZ28: =IS!CZ14-'BS and Cash Flow'!CZ88 -> 0
D29: =D24 -> vs. Total Interest | H29: =H28/H19 -> 1.2683402 | I29: =I28/I19 -> 1.3712756 | J29: =J28/J19 -> 1.590105 | K29: =K28/K19 -> 1.8714104 | L29: =L28/L19 -> 2.2459849 | M29: =M28/M19 -> 2.7481502 | N29: =N28/N19 -> 3.4464008 | O29: =O28/O19 -> 4.4853582 | CS29: =CS$28/CS19 -> #DIV/0! | CT29: =CT$28/CT19 -> #DIV/0! | CU29: =CU$28/CU19 -> #DIV/0! | CV29: =CV$28/CV19 -> #DIV/0! | CW29: =CW$28/CW19 -> #DIV/0! | CX29: =CX$28/CX19 -> #DIV/0! | CY29: =CY$28/CY19 -> #DIV/0! | CZ29: =CZ$28/CZ19 -> #DIV/0!
D30: =D25 -> vs. Net Interest | H30: =H28/H20 -> 1.2695654 | I30: =I28/I20 -> 1.3726163 | J30: =J28/J20 -> 1.5917179 | K30: =K28/K20 -> 1.8734294 | L30: =L28/L20 -> 2.2486231 | M30: =M28/M20 -> 2.751746 | N30: =N28/N20 -> 3.451566 | O30: =O28/O20 -> 4.4933745 | CS30: =CS$28/CS20 -> #DIV/0! | CT30: =CT$28/CT20 -> #DIV/0! | CU30: =CU$28/CU20 -> #DIV/0! | CV30: =CV$28/CV20 -> #DIV/0! | CW30: =CW$28/CW20 -> #DIV/0! | CX30: =CX$28/CX20 -> #DIV/0! | CY30: =CY$28/CY20 -> #DIV/0! | CZ30: =CZ$28/CZ20 -> #DIV/0!
D31: =D26 -> vs. Cash Interest (a) | H31: =H28/H21 -> 1.3255627 | I31: =I28/I21 -> 1.4339262 | J31: =J28/J21 -> 1.6656011 | K31: =K28/K21 -> 1.9661936 | L31: =L28/L21 -> 2.3703802 | M31: =M28/M21 -> 2.9187481 | N31: =N28/N21 -> 3.6936457 | O31: =O28/O21 -> 4.8743239 | CS31: =CS$28/CS21 -> #DIV/0! | CT31: =CT$28/CT21 -> #DIV/0! | CU31: =CU$28/CU21 -> #DIV/0! | CV31: =CV$28/CV21 -> #DIV/0! | CW31: =CW$28/CW21 -> #DIV/0! | CX31: =CX$28/CX21 -> #DIV/0! | CY31: =CY$28/CY21 -> #DIV/0! | CZ31: =CZ$28/CZ21 -> #DIV/0!
A33: x | B33: Leverage Ratios:
C34: Total Debt / Total Capitalization | H34: =H11/H16 -> 0.55040562 | I34: =I11/I16 -> 0.5399793 | J34: =J11/J16 -> 0.5064113 | K34: =K11/K16 -> 0.46689832 | L34: =L11/L16 -> 0.42071018 | M34: =M11/M16 -> 0.36726837 | N34: =N11/N16 -> 0.30603797 | O34: =O11/O16 -> 0.2364616 | CS34: =CS11/CS16 -> #DIV/0! | CT34: =CT11/CT16 -> #DIV/0! | CU34: =CU11/CU16 -> #DIV/0! | CV34: =CV11/CV16 -> #DIV/0! | CW34: =CW11/CW16 -> #DIV/0! | CX34: =CX11/CX16 -> #DIV/0! | CY34: =CY11/CY16 -> #DIV/0! | CZ34: =CZ11/CZ16 -> #DIV/0!
C35: Net Debt / Total Capitalization | H35: =H13/H16 -> 0.54938584 | I35: =I13/I16 -> 0.54101259 | J35: =J13/J16 -> 0.50744754 | K35: =K13/K16 -> 0.46793757 | L35: =L13/L16 -> 0.42175249 | M35: =M13/M16 -> 0.36831378 | N35: =N13/N16 -> 0.3070865 | O35: =O13/O16 -> 0.23751325 | CS35: =CS13/CS16 -> #DIV/0! | CT35: =CT13/CT16 -> #DIV/0! | CU35: =CU13/CU16 -> #DIV/0! | CV35: =CV13/CV16 -> #DIV/0! | CW35: =CW13/CW16 -> #DIV/0! | CX35: =CX13/CX16 -> #DIV/0! | CY35: =CY13/CY16 -> #DIV/0! | CZ35: =CZ13/CZ16 -> #DIV/0!
C37: Total Debt / Equity | H37: =H11/H15 -> 1.2242271 | I37: =I11/I15 -> 1.1738152 | J37: =J11/J15 -> 1.0259783 | K37: =K11/K15 -> 0.87581476 | L37: =L11/L15 -> 0.72625163 | M37: =M11/M15 -> 0.58044889 | N37: =N11/N15 -> 0.44100104 | O37: =O11/O15 -> 0.30969182 | CS37: =IF('S&U and Opening BS'!$D$3="Y","NM ",CS11/CS15) -> #DIV/0! | CT37: =IF('S&U and Opening BS'!$D$3="Y","NM ",CT11/CT15) -> #DIV/0! | CU37: =IF('S&U and Opening BS'!$D$3="Y","NM ",CU11/CU15) -> #DIV/0! | CV37: =IF('S&U and Opening BS'!$D$3="Y","NM ",CV11/CV15) -> #DIV/0! | CW37: =IF('S&U and Opening BS'!$D$3="Y","NM ",CW11/CW15) -> #DIV/0! | CX37: =IF('S&U and Opening BS'!$D$3="Y","NM ",CX11/CX15) -> #DIV/0! | CY37: =IF('S&U and Opening BS'!$D$3="Y","NM ",CY11/CY15) -> #DIV/0! | CZ37: =IF('S&U and Opening BS'!$D$3="Y","NM ",CZ11/CZ15) -> #DIV/0!
C38: Net Debt / Equity | H38: =H13/H15 -> 1.2219589 | I38: =I13/I15 -> 1.1760614 | J38: =J13/J15 -> 1.0280777 | K38: =K13/K15 -> 0.87776419 | L38: =L13/L15 -> 0.72805092 | M38: =M13/M15 -> 0.5821011 | N38: =N13/N15 -> 0.44251196 | O38: =O13/O15 -> 0.31106916 | CS38: =IF('S&U and Opening BS'!$D$3="Y","NM ",CS13/CS15) -> #DIV/0! | CT38: =IF('S&U and Opening BS'!$D$3="Y","NM ",CT13/CT15) -> #DIV/0! | CU38: =IF('S&U and Opening BS'!$D$3="Y","NM ",CU13/CU15) -> #DIV/0! | CV38: =IF('S&U and Opening BS'!$D$3="Y","NM ",CV13/CV15) -> #DIV/0! | CW38: =IF('S&U and Opening BS'!$D$3="Y","NM ",CW13/CW15) -> #DIV/0! | CX38: =IF('S&U and Opening BS'!$D$3="Y","NM ",CX13/CX15) -> #DIV/0! | CY38: =IF('S&U and Opening BS'!$D$3="Y","NM ",CY13/CY15) -> #DIV/0! | CZ38: =IF('S&U and Opening BS'!$D$3="Y","NM ",CZ13/CZ15) -> #DIV/0!
C40: Equity / Total Capitalization | H40: =H15/H16 -> 0.44959438 | I40: =I15/I16 -> 0.4600207 | J40: =J15/J16 -> 0.4935887 | K40: =K15/K16 -> 0.53310168 | L40: =L15/L16 -> 0.57928982 | M40: =M15/M16 -> 0.63273163 | N40: =N15/N16 -> 0.69396203 | O40: =O15/O16 -> 0.7635384 | CS40: =CS15/CS16 -> #DIV/0! | CT40: =CT15/CT16 -> #DIV/0! | CU40: =CU15/CU16 -> #DIV/0! | CV40: =CV15/CV16 -> #DIV/0! | CW40: =CW15/CW16 -> #DIV/0! | CX40: =CX15/CX16 -> #DIV/0! | CY40: =CY15/CY16 -> #DIV/0! | CZ40: =CZ15/CZ16 -> #DIV/0!
C42: Senior Debt / EBITDA | H42: =H9/H23 -> 6.777415 | I42: =I9/I23 -> 5.847085 | J42: =J9/J23 -> 4.8465704 | K42: =K9/K23 -> 3.9263751 | L42: =L9/L23 -> 3.0479012 | M42: =M9/M23 -> 2.2061858 | N42: =N9/N23 -> 1.397573 | O42: =O9/O23 -> 0.61870744 | CS42: =CS9/CS23 -> #DIV/0! | CT42: =CT9/CT23 -> #DIV/0! | CU42: =CU9/CU23 -> #DIV/0! | CV42: =CV9/CV23 -> #DIV/0! | CW42: =CW9/CW23 -> #DIV/0! | CX42: =CX9/CX23 -> #DIV/0! | CY42: =CY9/CY23 -> #DIV/0! | CZ42: =CZ9/CZ23 -> #DIV/0!
C43: Total Debt / EBITDA | H43: =H11/H23 -> 9.7326839 | I43: =I11/I23 -> 8.5185636 | J43: =J11/J23 -> 7.2919004 | K43: =K11/K23 -> 6.1811796 | L43: =L11/L23 -> 5.1313704 | M43: =M11/M23 -> 4.1352243 | N43: =N11/N23 -> 3.1871158 | O43: =O11/O23 -> 2.2819863 | CS43: =CS11/CS23 -> #DIV/0! | CT43: =CT11/CT23 -> #DIV/0! | CU43: =CU11/CU23 -> #DIV/0! | CV43: =CV11/CV23 -> #DIV/0! | CW43: =CW11/CW23 -> #DIV/0! | CX43: =CX11/CX23 -> #DIV/0! | CY43: =CY11/CY23 -> #DIV/0! | CZ43: =CZ11/CZ23 -> #DIV/0!
C44: Net Debt / EBITDA | H44: =H13/H23 -> 9.7146514 | I44: =I13/I23 -> 8.5348645 | J44: =J13/J23 -> 7.3068213 | K44: =K13/K23 -> 6.194938 | L44: =L13/L23 -> 5.1440834 | M44: =M13/M23 -> 4.146995 | N44: =N13/N23 -> 3.1980353 | O44: =O13/O23 -> 2.2921354 | CS44: =CS13/CS23 -> #DIV/0! | CT44: =CT13/CT23 -> #DIV/0! | CU44: =CU13/CU23 -> #DIV/0! | CV44: =CV13/CV23 -> #DIV/0! | CW44: =CW13/CW23 -> #DIV/0! | CX44: =CX13/CX23 -> #DIV/0! | CY44: =CY13/CY23 -> #DIV/0! | CZ44: =CZ13/CZ23 -> #DIV/0!
A46: x | B46: Cumulative Bank Debt Paydown | I46: =($H$9-I9)/$H$9 -> 0.045621504 | J46: =($H$9-J9)/$H$9 -> 0.13576868 | K46: =($H$9-K9)/$H$9 -> 0.24069577 | L46: =($H$9-L9)/$H$9 -> 0.36210864 | M46: =($H$9-M9)/$H$9 -> 0.50130601 | N46: =($H$9-N9)/$H$9 -> 0.65946219 | O46: =($H$9-O9)/$H$9 -> 0.83779912
B48: (a) Cash Interest Expense = Total Interest Expense less Amortization of Financing Fees

Sheet Returns
B1: ='S&U and Opening BS'!$B$17 -> Leveraged Buyout for Brady Coporation
B2: Returns Analysis - EBITDA Exit Multiple Method | N2: Transaction Date: | O2: =FYE -> 45869
B3: Dollars in Millions
B5: Initial Equity Investment: | F5: ='S&U and Opening BS'!H28 -> 2253.4273
B6: Diluted Ownership: | F6: ='S&U and Opening BS'!K28 -> 1
I7: Projected Fiscal Year
I8: =YEAR(FYE)+1 -> 2026 | J8: =I8+1 -> 2027 | K8: =J8+1 -> 2028 | L8: =K8+1 -> 2029 | M8: =L8+1 -> 2030 | N8: =M8+1 -> 2031 | O8: =N8+1 -> 2032
I9: 1 | J9: =I9+1 -> 2 | K9: =J9+1 -> 3 | L9: =K9+1 -> 4 | M9: =L9+1 -> 5 | N9: =M9+1 -> 6 | O9: =N9+1 -> 7
A10: x | B10: EBITDA | I10: =Ratios!I23 -> 306.73205 | J10: =Ratios!J23 -> 335.09921 | K10: =Ratios!K23 -> 363.41425 | L10: =Ratios!L23 -> 393.29984 | M10: =Ratios!M23 -> 424.78577 | N10: =Ratios!N23 -> 457.89802 | O10: =Ratios!O23 -> 492.65828
B12: Implied Enterprise Value @ EBITDA Multiple of: | Q12: Step
G13: =G14-Q13 -> 16.923566 | I13: =$G13*I$10 -> 5191.0001 | J13: =$G13*J$10 -> 5671.0734 | K13: =$G13*K$10 -> 6150.265 | L13: =$G13*L$10 -> 6656.0356 | M13: =$G13*M$10 -> 7188.89 | N13: =$G13*N$10 -> 7749.2672 | O13: =$G13*O$10 -> 8337.5347 | Q13: 0.5
G14: ='S&U and Opening BS'!N60 -> 17.423566 | I14: =$G14*I$10 -> 5344.3661 | J14: =$G14*J$10 -> 5838.623 | K14: =$G14*K$10 -> 6331.9721 | L14: =$G14*L$10 -> 6852.6855 | M14: =$G14*M$10 -> 7401.2828 | N14: =$G14*N$10 -> 7978.2162 | O14: =$G14*O$10 -> 8583.8638
G15: =G14+Q13 -> 17.923566 | I15: =$G15*I$10 -> 5497.7321 | J15: =$G15*J$10 -> 6006.1726 | K15: =$G15*K$10 -> 6513.6793 | L15: =$G15*L$10 -> 7049.3354 | M15: =$G15*M$10 -> 7613.6757 | N15: =$G15*N$10 -> 8207.1652 | O15: =$G15*O$10 -> 8830.193
B17: Less: Net Debt | I17: =-Ratios!I13 -> -2617.9165 | J17: =-Ratios!J13 -> -2448.51 | K17: =-Ratios!K13 -> -2251.3288 | L17: =-Ratios!L13 -> -2023.1671 | M17: =-Ratios!M13 -> -1761.5845 | N17: =-Ratios!N13 -> -1464.374 | O17: =-Ratios!O13 -> -1129.2395
A19: x | B19: Implied Equity Value @ EBITDA Multiple of:
G20: =G13 -> 16.923566 | I20: =I13+I$17 -> 2573.0836 | J20: =J13+J$17 -> 3222.5634 | K20: =K13+K$17 -> 3898.9362 | L20: =L13+L$17 -> 4632.8685 | M20: =M13+M$17 -> 5427.3055 | N20: =N13+N$17 -> 6284.8932 | O20: =O13+O$17 -> 7208.2952
G21: =G14 -> 17.423566 | I21: =I14+I$17 -> 2726.4496 | J21: =J14+J$17 -> 3390.113 | K21: =K14+K$17 -> 4080.6434 | L21: =L14+L$17 -> 4829.5184 | M21: =M14+M$17 -> 5639.6984 | N21: =N14+N$17 -> 6513.8422 | O21: =O14+O$17 -> 7454.6244
G22: =G15 -> 17.923566 | I22: =I15+I$17 -> 2879.8156 | J22: =J15+J$17 -> 3557.6626 | K22: =K15+K$17 -> 4262.3505 | L22: =L15+L$17 -> 5026.1683 | M22: =M15+M$17 -> 5852.0913 | N22: =N15+N$17 -> 6742.7912 | O22: =O15+O$17 -> 7700.9535
A24: x | B24: Equity Return @ EBITDA Multiple of:
G25: =G13 -> 16.923566 | I25: =RATE(COUNT($I$9:I$9), 0, -$F$5, I$20) -> 0.14185336 | J25: =RATE(COUNT($I$9:J$9), 0, -$F$5, J$20) -> 0.1958562 | K25: =RATE(COUNT($I$9:K$9), 0, -$F$5, K$20) -> 0.20051482 | L25: =RATE(COUNT($I$9:L$9), 0, -$F$5, L$20) -> 0.19743405 | M25: =RATE(COUNT($I$9:M$9), 0, -$F$5, M$20) -> 0.19219732 | N25: =RATE(COUNT($I$9:N$9), 0, -$F$5, N$20) -> 0.18643074 | O25: =RATE(COUNT($I$9:O$9), 0, -$F$5, O$20) -> 0.18070469
G26: =G14 -> 17.423566 | I26: =RATE(COUNT($I$9:I$9), 0, -$F$5, I$21) -> 0.20991237 | J26: =RATE(COUNT($I$9:J$9), 0, -$F$5, J$21) -> 0.22655015 | K26: =RATE(COUNT($I$9:K$9), 0, -$F$5, K$21) -> 0.21888209 | L26: =RATE(COUNT($I$9:L$9), 0, -$F$5, L$21) -> 0.20994343 | M26: =RATE(COUNT($I$9:M$9), 0, -$F$5, M$21) -> 0.20138572 | N26: =RATE(COUNT($I$9:N$9), 0, -$F$5, N$21) -> 0.19352709 | O26: =RATE(COUNT($I$9:O$9), 0, -$F$5, O$21) -> 0.18638605
G27: =G15 -> 17.923566 | I27: =RATE(COUNT($I$9:I$9), 0, -$F$5, I$22) -> 0.27797138 | J27: =RATE(COUNT($I$9:J$9), 0, -$F$5, J$22) -> 0.25649453 | K27: =RATE(COUNT($I$9:K$9), 0, -$F$5, K$22) -> 0.23671189 | L27: =RATE(COUNT($I$9:L$9), 0, -$F$5, L$22) -> 0.22207643 | M27: =RATE(COUNT($I$9:M$9), 0, -$F$5, M$22) -> 0.21030132 | N27: =RATE(COUNT($I$9:N$9), 0, -$F$5, N$22) -> 0.20041853 | O27: =RATE(COUNT($I$9:O$9), 0, -$F$5, O$22) -> 0.19190871
B30: ='S&U and Opening BS'!$B$17 -> Leveraged Buyout for Brady Coporation
B31: Returns Analysis - IPO Exit | N31: Transaction Date: | O31: =FYE -> 45869
B32: Dollars in Millions
B34: Initial Equity Investment: | F34: 0
B35: Diluted Ownership: | F35: 0
I36: Projected Fiscal Year
I37: =YEAR(FYE)+1 -> 2026 | J37: =I37+1 -> 2027 | K37: =J37+1 -> 2028 | L37: =K37+1 -> 2029 | M37: =L37+1 -> 2030 | N37: =M37+1 -> 2031 | O37: =N37+1 -> 2032 | Q37: Growth Rate
I38: 1 | J38: =I38+1 -> 2 | K38: =J38+1 -> 3 | L38: =K38+1 -> 4 | M38: =L38+1 -> 5 | N38: =M38+1 -> 6 | O38: =N38+1 -> 7 | Q38: ="for "&O37 -> for 2032
A39: x | B39: One Year Forward Net Income | I39: 0 | J39: 0 | K39: 0 | L39: 0 | M39: 0 | N39: 0 | O39: 0 | Q39: =N39/M39-1 -> #DIV/0!
A41: x | B41: Implied Equity Value @ Net Income Multiple of: | Q41: Step
G42: 19 | I42: 0 | J42: 0 | K42: 0 | L42: 0 | M42: 0 | N42: 0 | O42: 0 | Q42: 1
G43: =G42+$Q$42 -> 20 | I43: 0 | J43: 0 | K43: 0 | L43: 0 | M43: 0 | N43: 0 | O43: 0
G44: =G43+$Q$42 -> 21 | I44: 0 | J44: 0 | K44: 0 | L44: 0 | M44: 0 | N44: 0 | O44: 0
A46: x | B46: Equity Return @ Net Income Multiple of:
G47: =G42 -> 19 | I47: 0 | J47: 0 | K47: 0 | L47: 0 | M47: 0 | N47: 0 | O47: 0
G48: =G43 -> 20 | I48: 0 | J48: 0 | K48: 0 | L48: 0 | M48: 0 | N48: 0 | O48: 0
A49: x | G49: =G44 -> 21 | I49: 0 | J49: 0 | K49: 0 | L49: 0 | M49: 0 | N49: 0 | O49: 0
